Workbook

Sheet README
A1: Bantaba Remittance — 5-Year Financial Model
A3: Version 1.0 · October 2026 · Reporting currency: US dollars · Planning-grade estimates
A5: PURPOSE
A6: Shows how Bantaba (a cash-to-code remittance company, not a fintech) grows volume across six corridors, earns fees and FX margin, pays for payout partners and operations, and what funding is required.
A8: HOW TO USE
A9: 1. Go to 'Assumptions'. Blue text on cream fill = inputs you may change. Black = formulas. Green = links to other sheets.
A10: 2. Change the scenario selector (cell B3: 1=Base, 2=Conservative, 3=Upside). Every sheet recalculates.
A11: 3. 'Monthly' holds the 60-month engine. 'Annual' summarises it. 'Unit_Economics' shows one transfer. 'Float_Treasury' sizes prefunded payout float. 'Scenarios' is a static snapshot of all three cases.
A13: KEY STRUCTURE
A14: • Transfers per corridor = cap × (1 − e^(−months since launch / ramp τ)) × seasonality × scenario multiplier. Volume = transfers × average ticket.
A15: • Revenue = volume × (fee % + FX margin %). Variable costs are % of volume. Fixed costs come from the headcount plan plus non-payroll lines.
A16: • Cash = EBITDA − capex − change in prefunded float + equity raised. Float = days of cover × daily volume.
... A23: • Gambia inflow base: US$872M in 2025 (Central Bank of The Gambia, announced at Stake in the Nation Forum 9); US$775.6M in 2024.

Sheet Assumptions
A1: Assumptions (blue = input)
C2: Active scenario | D2: Volume × | E2: Fixed cost ×
A3: Scenario selector (1=Base, 2=Conservative, 3=Upside) | B3: 1 | C3: =INDEX(B6:B8,B3) -> Base | D3: =INDEX(C6:C8,B3) -> 1 | E3: =INDEX(D6:D8,B3) -> 1
A5: # | B5: Scenario | C5: Volume multiplier | D5: Fixed-cost multiplier
A6: 1 | B6: Base | C6: 1 | D6: 1
A7: 2 | B7: Conservative | C7: 0.6 | D7: 1
A8: 3 | B8: Upside | C8: 1.3 | D8: 1
A11: Corridor | B11: Launch month | C11: Mature monthly transfers (cap) | D11: Ramp τ (months) | E11: Avg ticket (USD) | F11: Fee % of volume | G11: FX margin % of volume | H11: Total take % | I11: Gambia-bound (1/0)
A12: UK → Gambia | B12: 11 | C12: 20000 | D12: 12 | E12: 230 | F12: 0.025 | G12: 0.015 | H12: =F12+G12 -> 0.04 | I12: 1
A13: China → Gambia | B13: 15 | C13: 13000 | D13: 12 | E13: 320 | F13: 0.021 | G13: 0.015 | H13: =F13+G13 -> 0.036 | I13: 1
A14: USA → Gambia | B14: 19 | C14: 10000 | D14: 12 | E14: 300 | F14: 0.023 | G14: 0.015 | H14: =F14+G14 -> 0.038 | I14: 1
A15: Regional: Senegal (Dakar) | B15: 25 | C15: 24000 | D15: 12 | E15: 110 | F15: 0.024 | G15: 0.012 | H15: =F15+G15 -> 0.036 | I15: 0
A16: Regional: Guinea (Conakry) | B16: 31 | C16: 10000 | D16: 12 | E16: 130 | F16: 0.026 | G16: 0.02 | H16: =F16+G16 -> 0.046 | I16: 0
A17: Regional: Guinea-Bissau (Bissau) | B17: 31 | C17: 7000 | D17: 12 | E17: 110 | F17: 0.024 | G17: 0.012 | H17: =F17+G17 -> 0.036 | I17: 0
A18: Launch month = month since funding close (M1). UK launches at M11 (public beta after closed pilot M9–10); China M15 after legal gating; USA M19; regional corridors M25–M31.
A20: Seasonality index (Eid, Tobaski, Ramadan, school terms, December)
A21: Month of year | B21: 1 | C21: 2 | D21: 3 | E21: 4 | F21: 5 | G21: 6 | H21: 7 | I21: 8 | J21: 9 | K21: 10 | L21: 11 | M21: 12
A22: Index | B22: 0.95 | C22: 0.95 | D22: 1 | E22: 1.1 | F22: 1 | G22: 1.05 | H22: 0.95 | I22: 0.95 | J22: 0.95 | K22: 1 | L22: 1 | M22: 1.15
A25: Variable costs (% of volume) | B25: %
A26: Payout partner / agent commission | B26: 0.007
A27: Origin send-point / agent commission | B27: 0.0025
A28: Banking, settlement & FX execution | B28: 0.003
A29: Fraud & loss provision | B29: 0.001
A30: KYC, screening, SMS/WhatsApp | B30: 0.0012
A31: Cash logistics & cash-in-transit insurance | B31: 0.0015
A32: Total variable cost % of volume | B32: =SUM(B26:B31) -> 0.0162
A35: Fixed operating costs (USD / year) | B35: Y1 | C35: Y2 | D35: Y3 | E35: Y4 | F35: Y5
A36: Payroll (from Headcount sheet) | B36: =Headcount!J16 -> 725500 | C36: =Headcount!K16 -> 1108500 | D36: =Headcount!L16 -> 1557500 | E36: =Headcount!M16 -> 1892500 | F36: =Headcount!N16 -> 2042000
A37: Premises & send points (rent, fit-out, security) | B37: 60000 | C37: 200000 | D37: 300000 | E37: 360000 | F37: 400000
A38: Licensing, legal, audit & compliance tooling | B38: 280000 | C38: 360000 | D38: 360000 | E38: 380000 | F38: 400000
A39: Technology, cloud & vendors (IDV, screening, SMS) | B39: 140000 | C39: 220000 | D39: 300000 | E39: 380000 | F39: 420000
A40: Marketing & community ambassadors | B40: 50000 | C40: 220000 | D40: 320000 | E40: 340000 | F40: 360000
A41: G&A (insurance, travel, accounting) | B41: 80000 | C41: 150000 | D41: 200000 | E41: 240000 | F41: 260000
A42: Total fixed operating costs (before scenario multiplier) | B42: =SUM(B36:B41) -> 1335500 | C42: =SUM(C36:C41) -> 2258500 | D42: =SUM(D36:D41) -> 3037500 | E42: =SUM(E36:E41) -> 3592500 | F42: =SUM(F36:F41) -> 3882000
A43: Capital expenditure (equipment, fit-out, security systems) | B43: 200000 | C43: 250000 | D43: 300000 | E43: 300000 | F43: 300000
A46: Financing, working capital & market inputs | B46: Value
A47: Seed round (USD) | B47: 4000000
A48: Seed received in month | B48: 1
A49: Series A (USD) | B49: 5000000
A50: Series A received in month | B50: 22
...

Sheet Headcount
A1: Headcount plan & payroll
A3: Function | B3: Loaded cost (USD/yr) | C3: Opening | D3: Y1 | E3: Y2 | F3: Y3 | G3: Y4 | H3: Y5 | J3: Payroll Y1 | K3: Payroll Y2 | L3: Payroll Y3 | M3: Payroll Y4 | N3: Payroll Y5
A4: Executive & leadership | B4: 90000 | C4: 3 | D4: 3 | E4: 3 | F4: 4 | G4: 4 | H4: 4 | J4: =AVERAGE(C4,D4)*$B4 -> 270000 | K4: =AVERAGE(D4,E4)*$B4 -> 270000 | L4: =AVERAGE(E4,F4)*$B4 -> 315000 | M4: =AVERAGE(F4,G4)*$B4 -> 360000 | N4: =AVERAGE(G4,H4)*$B4 -> 360000
A5: Engineering & product | B5: 70000 | C5: 3 | D5: 4 | E5: 5 | F5: 6 | G5: 6 | H5: 7 | J5: =AVERAGE(C5,D5)*$B5 -> 245000 | K5: =AVERAGE(D5,E5)*$B5 -> 315000 | L5: =AVERAGE(E5,F5)*$B5 -> 385000 | M5: =AVERAGE(F5,G5)*$B5 -> 420000 | N5: =AVERAGE(G5,H5)*$B5 -> 455000
A6: Compliance & risk (MLRO, analysts) | B6: 55000 | C6: 1 | D6: 2 | E6: 3 | F6: 4 | G6: 5 | H6: 5 | J6: =AVERAGE(C6,D6)*$B6 -> 82500 | K6: =AVERAGE(D6,E6)*$B6 -> 137500 | L6: =AVERAGE(E6,F6)*$B6 -> 192500 | M6: =AVERAGE(F6,G6)*$B6 -> 247500 | N6: =AVERAGE(G6,H6)*$B6 -> 275000
A7: Treasury & finance | B7: 50000 | C7: 0 | D7: 1 | E7: 2 | F7: 3 | G7: 3 | H7: 3 | J7: =AVERAGE(C7,D7)*$B7 -> 25000 | K7: =AVERAGE(D7,E7)*$B7 -> 75000 | L7: =AVERAGE(E7,F7)*$B7 -> 125000 | M7: =AVERAGE(F7,G7)*$B7 -> 150000 | N7: =AVERAGE(G7,H7)*$B7 -> 150000
A8: Operations & customer support (HQ) | B8: 20000 | C8: 1 | D8: 3 | E8: 5 | F8: 7 | G8: 9 | H8: 10 | J8: =AVERAGE(C8,D8)*$B8 -> 40000 | K8: =AVERAGE(D8,E8)*$B8 -> 80000 | L8: =AVERAGE(E8,F8)*$B8 -> 120000 | M8: =AVERAGE(F8,G8)*$B8 -> 160000 | N8: =AVERAGE(G8,H8)*$B8 -> 190000
A9: Send points — UK | B9: 36000 | C9: 0 | D9: 2 | E9: 4 | F9: 5 | G9: 5 | H9: 5 | J9: =AVERAGE(C9,D9)*$B9 -> 36000 | K9: =AVERAGE(D9,E9)*$B9 -> 108000 | L9: =AVERAGE(E9,F9)*$B9 -> 162000 | M9: =AVERAGE(F9,G9)*$B9 -> 180000 | N9: =AVERAGE(G9,H9)*$B9 -> 180000
A10: Send points — China | B10: 18000 | C10: 0 | D10: 0 | E10: 3 | F10: 4 | G10: 5 | H10: 5 | J10: =AVERAGE(C10,D10)*$B10 -> 0 | K10: =AVERAGE(D10,E10)*$B10 -> 27000 | L10: =AVERAGE(E10,F10)*$B10 -> 63000 | M10: =AVERAGE(F10,G10)*$B10 -> 81000 | N10: =AVERAGE(G10,H10)*$B10 -> 90000
A11: Send points — USA | B11: 30000 | C11: 0 | D11: 0 | E11: 1 | F11: 3 | G11: 4 | H11: 4 | J11: =AVERAGE(C11,D11)*$B11 -> 0 | K11: =AVERAGE(D11,E11)*$B11 -> 15000 | L11: =AVERAGE(E11,F11)*$B11 -> 60000 | M11: =AVERAGE(F11,G11)*$B11 -> 105000 | N11: =AVERAGE(G11,H11)*$B11 -> 120000
A12: Payout & agent team — Gambia & region | B12: 12000 | C12: 0 | D12: 2 | E12: 4 | F12: 6 | G12: 8 | H12: 9 | J12: =AVERAGE(C12,D12)*$B12 -> 12000 | K12: =AVERAGE(D12,E12)*$B12 -> 36000 | L12: =AVERAGE(E12,F12)*$B12 -> 60000 | M12: =AVERAGE(F12,G12)*$B12 -> 84000 | N12: =AVERAGE(G12,H12)*$B12 -> 102000
A13: Growth & community | B13: 30000 | C13: 0 | D13: 1 | E13: 2 | F13: 3 | G13: 4 | H13: 4 | J13: =AVERAGE(C13,D13)*$B13 -> 15000 | K13: =AVERAGE(D13,E13)*$B13 -> 45000 | L13: =AVERAGE(E13,F13)*$B13 -> 75000 | M13: =AVERAGE(F13,G13)*$B13 -> 105000 | N13: =AVERAGE(G13,H13)*$B13 -> 120000
A16: Total | C16: =SUM(C4:C13) -> 8 | D16: =SUM(D4:D13) -> 18 | E16: =SUM(E4:E13) -> 32 | F16: =SUM(F4:F13) -> 45 | G16: =SUM(G4:G13) -> 53 | H16: =SUM(H4:H13) -> 56 | J16: =SUM(J4:J13) -> 725500 | K16: =SUM(K4:K13) -> 1108500 | L16: =SUM(L4:L13) -> 1557500 | M16: =SUM(M4:M13) -> 1892500 | N16: =SUM(N4:N13) -> 2042000
A18: Payroll = average of opening and closing heads × loaded cost (salary + on-costs). Locations: UK/US at local market cost, China and Gambia at local cost. Contractors for the MVP build are included in Engineering.

Sheet Monthly
A1: Monthly engine (60 months)
A3: Line | B3: Unit | C3: M1 | D3: M2 | E3: M3 | F3: M4 | G3: M5 | H3: M6 | I3: M7 | J3: M8 | K3: M9 | L3: M10 | M3: M11 | N3: M12 | O3: M13 | P3: M14 | Q3: M15 | R3: M16 | S3: M17 | T3: M18 | U3: M19 | V3: M20 | W3: M21 | X3: M22 | Y3: M23 | Z3: M24 | AA3: M25 | AB3: M26 | AC3: M27 | AD3: M28 | AE3: M29 | AF3: M30 | AG3: M31 | AH3: M32 | AI3: M33 | AJ3: M34 | AK3: M35 | AL3: M36 | AM3: M37 | AN3: M38 | AO3: M39 | AP3: M40 | AQ3: M41 | AR3: M42 | AS3: M43 | AT3: M44 | AU3: M45 | AV3: M46 | AW3: M47 | AX3: M48 | AY3: M49 | AZ3: M50 | BA3: M51 | BB3: M52 | BC3: M53 | BD3: M54 | BE3: M55 | BF3: M56 | BG3: M57 | BH3: M58 | BI3: M59 | BJ3: M60
A4: Month index | B4: # | C4: 1 | D4: 2 | E4: 3 | F4: 4 | G4: 5 | H4: 6 | I4: 7 | J4: 8 | K4: 9 | L4: 10 | M4: 11 | N4: 12 | O4: 13 | P4: 14 | Q4: 15 | R4: 16 | S4: 17 | T4: 18 | U4: 19 | V4: 20 | W4: 21 | X4: 22 | Y4: 23 | Z4: 24 | AA4: 25 | AB4: 26 | AC4: 27 | AD4: 28 | AE4: 29 | AF4: 30 | AG4: 31 | AH4: 32 | AI4: 33 | AJ4: 34 | AK4: 35 | AL4: 36 | AM4: 37 | AN4: 38 | AO4: 39 | AP4: 40 | AQ4: 41 | AR4: 42 | AS4: 43 | AT4: 44 | AU4: 45 | AV4: 46 | AW4: 47 | AX4: 48 | AY4: 49 | AZ4: 50 | BA4: 51 | BB4: 52 | BC4: 53 | BD4: 54 | BE4: 55 | BF4: 56 | BG4: 57 | BH4: 58 | BI4: 59 | BJ4: 60
A5: Year | B5: # | C5: =INT((C4-1)/12)+1 -> 1 | D5: =INT((D4-1)/12)+1 -> 1 | E5: =INT((E4-1)/12)+1 -> 1 | F5: =INT((F4-1)/12)+1 -> 1 | G5: =INT((G4-1)/12)+1 -> 1 | H5: =INT((H4-1)/12)+1 -> 1 | I5: =INT((I4-1)/12)+1 -> 1 | J5: =INT((J4-1)/12)+1 -> 1 | ... BJ5: =INT((BJ4-1)/12)+1 -> 5
A6: Month of year | B6: # | C6: =MOD(C4-1,12)+1 -> 1 | D6: =MOD(D4-1,12)+1 -> 2 | E6: =MOD(E4-1,12)+1 -> 3 | F6: =MOD(F4-1,12)+1 -> 4 | G6: =MOD(G4-1,12)+1 -> 5 | H6: =MOD(H4-1,12)+1 -> 6 | I6: =MOD(I4-1,12)+1 -> 7 | J6: =MOD(J4-1,12)+1 -> 8 | ... BJ6: =MOD(BJ4-1,12)+1 -> 12
A7: Seasonality index | B7: x | C7: =INDEX(Assumptions!$B$22:$M$22,C6) -> 0.95 | D7: =INDEX(Assumptions!$B$22:$M$22,D6) -> 0.95 | E7: =INDEX(Assumptions!$B$22:$M$22,E6) -> 1 | F7: =INDEX(Assumptions!$B$22:$M$22,F6) -> 1.1 | G7: =INDEX(Assumptions!$B$22:$M$22,G6) -> 1 | H7: =INDEX(Assumptions!$B$22:$M$22,H6) -> 1.05 | I7: =INDEX(Assumptions!$B$22:$M$22,I6) -> 0.95 | J7: =INDEX(Assumptions!$B$22:$M$22,J6) -> 0.95 | ... BJ7: =INDEX(Assumptions!$B$22:$M$22,BJ6) -> 1.15
A8: Scenario volume multiplier | B8: x | C8: =Assumptions!$D$3 -> 1 | D8: =Assumptions!$D$3 -> 1 | E8: =Assumptions!$D$3 -> 1 | F8: =Assumptions!$D$3 -> 1 | G8: =Assumptions!$D$3 -> 1 | H8: =Assumptions!$D$3 -> 1 | I8: =Assumptions!$D$3 -> 1 | J8: =Assumptions!$D$3 -> 1 | ... BJ8: =Assumptions!$D$3 -> 1
A10: TRANSFERS (count)
A11: =Assumptions!A12 -> UK → Gambia | B11: count | C11: =IF(C$4<Assumptions!$B$12,0,Assumptions!$C$12*(1-EXP(-(C$4-Assumptions!$B$12+1)/Assumptions!$D$12))*C$7*C$8) -> 0 | D11: =IF(D$4<Assumptions!$B$12,0,Assumptions!$C$12*(1-EXP(-(D$4-Assumptions!$B$12+1)/Assumptions!$D$12))*D$7*D$8) -> 0 | E11: =IF(E$4<Assumptions!$B$12,0,Assumptions!$C$12*(1-EXP(-(E$4-Assumptions!$B$12+1)/Assumptions!$D$12))*E$7*E$8) -> 0 | F11: =IF(F$4<Assumptions!$B$12,0,Assumptions!$C$12*(1-EXP(-(F$4-Assumptions!$B$12+1)/Assumptions!$D$12))*F$7*F$8) -> 0 | G11: =IF(G$4<Assumptions!$B$12,0,Assumptions!$C$12*(1-EXP(-(G$4-Assumptions!$B$12+1)/Assumptions!$D$12))*G$7*G$8) -> 0 | H11: =IF(H$4<Assumptions!$B$12,0,Assumptions!$C$12*(1-EXP(-(H$4-Assumptions!$B$12+1)/Assumptions!$D$12))*H$7*H$8) -> 0 | I11: =IF(I$4<Assumptions!$B$12,0,Assumptions!$C$12*(1-EXP(-(I$4-Assumptions!$B$12+1)/Assumptions!$D$12))*I$7*I$8) -> 0 | J11: =IF(J$4<Assumptions!$B$12,0,Assumptions!$C$12*(1-EXP(-(J$4-Assumptions!$B$12+1)/Assumptions!$D$12))*J$7*J$8) -> 0 | ... BJ11: =IF(BJ$4<Assumptions!$B$12,0,Assumptions!$C$12*(1-EXP(-(BJ$4-Assumptions!$B$12+1)/Assumptions!$D$12))*BJ$7*BJ$8) -> 22643.411
A12: =Assumptions!A13 -> China → Gambia | B12: count | C12: =IF(C$4<Assumptions!$B$13,0,Assumptions!$C$13*(1-EXP(-(C$4-Assumptions!$B$13+1)/Assumptions!$D$13))*C$7*C$8) -> 0 | D12: =IF(D$4<Assumptions!$B$13,0,Assumptions!$C$13*(1-EXP(-(D$4-Assumptions!$B$13+1)/Assumptions!$D$13))*D$7*D$8) -> 0 | E12: =IF(E$4<Assumptions!$B$13,0,Assumptions!$C$13*(1-EXP(-(E$4-Assumptions!$B$13+1)/Assumptions!$D$13))*E$7*E$8) -> 0 | F12: =IF(F$4<Assumptions!$B$13,0,Assumptions!$C$13*(1-EXP(-(F$4-Assumptions!$B$13+1)/Assumptions!$D$13))*F$7*F$8) -> 0 | G12: =IF(G$4<Assumptions!$B$13,0,Assumptions!$C$13*(1-EXP(-(G$4-Assumptions!$B$13+1)/Assumptions!$D$13))*G$7*G$8) -> 0 | H12: =IF(H$4<Assumptions!$B$13,0,Assumptions!$C$13*(1-EXP(-(H$4-Assumptions!$B$13+1)/Assumptions!$D$13))*H$7*H$8) -> 0 | I12: =IF(I$4<Assumptions!$B$13,0,Assumptions!$C$13*(1-EXP(-(I$4-Assumptions!$B$13+1)/Assumptions!$D$13))*I$7*I$8) -> 0 | J12: =IF(J$4<Assumptions!$B$13,0,Assumptions!$C$13*(1-EXP(-(J$4-Assumptions!$B$13+1)/Assumptions!$D$13))*J$7*J$8) -> 0 | ... BJ12: =IF(BJ$4<Assumptions!$B$13,0,Assumptions!$C$13*(1-EXP(-(BJ$4-Assumptions!$B$13+1)/Assumptions!$D$13))*BJ$7*BJ$8) -> 14626.521
A13: =Assumptions!A14 -> USA → Gambia | B13: count | C13: =IF(C$4<Assumptions!$B$14,0,Assumptions!$C$14*(1-EXP(-(C$4-Assumptions!$B$14+1)/Assumptions!$D$14))*C$7*C$8) -> 0 | D13: =IF(D$4<Assumptions!$B$14,0,Assumptions!$C$14*(1-EXP(-(D$4-Assumptions!$B$14+1)/Assumptions!$D$14))*D$7*D$8) -> 0 | E13: =IF(E$4<Assumptions!$B$14,0,Assumptions!$C$14*(1-EXP(-(E$4-Assumptions!$B$14+1)/Assumptions!$D$14))*E$7*E$8) -> 0 | F13: =IF(F$4<Assumptions!$B$14,0,Assumptions!$C$14*(1-EXP(-(F$4-Assumptions!$B$14+1)/Assumptions!$D$14))*F$7*F$8) -> 0 | G13: =IF(G$4<Assumptions!$B$14,0,Assumptions!$C$14*(1-EXP(-(G$4-Assumptions!$B$14+1)/Assumptions!$D$14))*G$7*G$8) -> 0 | H13: =IF(H$4<Assumptions!$B$14,0,Assumptions!$C$14*(1-EXP(-(H$4-Assumptions!$B$14+1)/Assumptions!$D$14))*H$7*H$8) -> 0 | I13: =IF(I$4<Assumptions!$B$14,0,Assumptions!$C$14*(1-EXP(-(I$4-Assumptions!$B$14+1)/Assumptions!$D$14))*I$7*I$8) -> 0 | J13: =IF(J$4<Assumptions!$B$14,0,Assumptions!$C$14*(1-EXP(-(J$4-Assumptions!$B$14+1)/Assumptions!$D$14))*J$7*J$8) -> 0 | ... BJ13: =IF(BJ$4<Assumptions!$B$14,0,Assumptions!$C$14*(1-EXP(-(BJ$4-Assumptions!$B$14+1)/Assumptions!$D$14))*BJ$7*BJ$8) -> 11152.73
A14: =Assumptions!A15 -> Regional: Senegal (Dakar) | B14: count | C14: =IF(C$4<Assumptions!$B$15,0,Assumptions!$C$15*(1-EXP(-(C$4-Assumptions!$B$15+1)/Assumptions!$D$15))*C$7*C$8) -> 0 | D14: =IF(D$4<Assumptions!$B$15,0,Assumptions!$C$15*(1-EXP(-(D$4-Assumptions!$B$15+1)/Assumptions!$D$15))*D$7*D$8) -> 0 | E14: =IF(E$4<Assumptions!$B$15,0,Assumptions!$C$15*(1-EXP(-(E$4-Assumptions!$B$15+1)/Assumptions!$D$15))*E$7*E$8) -> 0 | F14: =IF(F$4<Assumptions!$B$15,0,Assumptions!$C$15*(1-EXP(-(F$4-Assumptions!$B$15+1)/Assumptions!$D$15))*F$7*F$8) -> 0 | G14: =IF(G$4<Assumptions!$B$15,0,Assumptions!$C$15*(1-EXP(-(G$4-Assumptions!$B$15+1)/Assumptions!$D$15))*G$7*G$8) -> 0 | H14: =IF(H$4<Assumptions!$B$15,0,Assumptions!$C$15*(1-EXP(-(H$4-Assumptions!$B$15+1)/Assumptions!$D$15))*H$7*H$8) -> 0 | I14: =IF(I$4<Assumptions!$B$15,0,Assumptions!$C$15*(1-EXP(-(I$4-Assumptions!$B$15+1)/Assumptions!$D$15))*I$7*I$8) -> 0 | J14: =IF(J$4<Assumptions!$B$15,0,Assumptions!$C$15*(1-EXP(-(J$4-Assumptions!$B$15+1)/Assumptions!$D$15))*J$7*J$8) -> 0 | ... BJ14: =IF(BJ$4<Assumptions!$B$15,0,Assumptions!$C$15*(1-EXP(-(BJ$4-Assumptions!$B$15+1)/Assumptions!$D$15))*BJ$7*BJ$8) -> 26225.877
A15: =Assumptions!A16 -> Regional: Guinea (Conakry) | B15: count | C15: =IF(C$4<Assumptions!$B$16,0,Assumptions!$C$16*(1-EXP(-(C$4-Assumptions!$B$16+1)/Assumptions!$D$16))*C$7*C$8) -> 0 | D15: =IF(D$4<Assumptions!$B$16,0,Assumptions!$C$16*(1-EXP(-(D$4-Assumptions!$B$16+1)/Assumptions!$D$16))*D$7*D$8) -> 0 | E15: =IF(E$4<Assumptions!$B$16,0,Assumptions!$C$16*(1-EXP(-(E$4-Assumptions!$B$16+1)/Assumptions!$D$16))*E$7*E$8) -> 0 | F15: =IF(F$4<Assumptions!$B$16,0,Assumptions!$C$16*(1-EXP(-(F$4-Assumptions!$B$16+1)/Assumptions!$D$16))*F$7*F$8) -> 0 | G15: =IF(G$4<Assumptions!$B$16,0,Assumptions!$C$16*(1-EXP(-(G$4-Assumptions!$B$16+1)/Assumptions!$D$16))*G$7*G$8) -> 0 | H15: =IF(H$4<Assumptions!$B$16,0,Assumptions!$C$16*(1-EXP(-(H$4-Assumptions!$B$16+1)/Assumptions!$D$16))*H$7*H$8) -> 0 | I15: =IF(I$4<Assumptions!$B$16,0,Assumptions!$C$16*(1-EXP(-(I$4-Assumptions!$B$16+1)/Assumptions!$D$16))*I$7*I$8) -> 0 | J15: =IF(J$4<Assumptions!$B$16,0,Assumptions!$C$16*(1-EXP(-(J$4-Assumptions!$B$16+1)/Assumptions!$D$16))*J$7*J$8) -> 0 | ... BJ15: =IF(BJ$4<Assumptions!$B$16,0,Assumptions!$C$16*(1-EXP(-(BJ$4-Assumptions!$B$16+1)/Assumptions!$D$16))*BJ$7*BJ$8) -> 10556.023
A16: =Assumptions!A17 -> Regional: Guinea-Bissau (Bissau) | B16: count | C16: =IF(C$4<Assumptions!$B$17,0,Assumptions!$C$17*(1-EXP(-(C$4-Assumptions!$B$17+1)/Assumptions!$D$17))*C$7*C$8) -> 0 | D16: =IF(D$4<Assumptions!$B$17,0,Assumptions!$C$17*(1-EXP(-(D$4-Assumptions!$B$17+1)/Assumptions!$D$17))*D$7*D$8) -> 0 | E16: =IF(E$4<Assumptions!$B$17,0,Assumptions!$C$17*(1-EXP(-(E$4-Assumptions!$B$17+1)/Assumptions!$D$17))*E$7*E$8) -> 0 | F16: =IF(F$4<Assumptions!$B$17,0,Assumptions!$C$17*(1-EXP(-(F$4-Assumptions!$B$17+1)/Assumptions!$D$17))*F$7*F$8) -> 0 | G16: =IF(G$4<Assumptions!$B$17,0,Assumptions!$C$17*(1-EXP(-(G$4-Assumptions!$B$17+1)/Assumptions!$D$17))*G$7*G$8) -> 0 | H16: =IF(H$4<Assumptions!$B$17,0,Assumptions!$C$17*(1-EXP(-(H$4-Assumptions!$B$17+1)/Assumptions!$D$17))*H$7*H$8) -> 0 | I16: =IF(I$4<Assumptions!$B$17,0,Assumptions!$C$17*(1-EXP(-(I$4-Assumptions!$B$17+1)/Assumptions!$D$17))*I$7*I$8) -> 0 | J16: =IF(J$4<Assumptions!$B$17,0,Assumptions!$C$17*(1-EXP(-(J$4-Assumptions!$B$17+1)/Assumptions!$D$17))*J$7*J$8) -> 0 | ... BJ16: =IF(BJ$4<Assumptions!$B$17,0,Assumptions!$C$17*(1-EXP(-(BJ$4-Assumptions!$B$17+1)/Assumptions!$D$17))*BJ$7*BJ$8) -> 7389.2158
A17: Total transfers | B17: count | C17: =SUM(C11:C16) -> 0 | D17: =SUM(D11:D16) -> 0 | E17: =SUM(E11:E16) -> 0 | F17: =SUM(F11:F16) -> 0 | G17: =SUM(G11:G16) -> 0 | H17: =SUM(H11:H16) -> 0 | I17: =SUM(I11:I16) -> 0 | J17: =SUM(J11:J16) -> 0 | ... BJ17: =SUM(BJ11:BJ16) -> 92593.778
A19: VOLUME SENT (USD)
A20: =Assumptions!A12 -> UK → Gambia | B20: USD | C20: =C11*Assumptions!$E$12 -> 0 | D20: =D11*Assumptions!$E$12 -> 0 | E20: =E11*Assumptions!$E$12 -> 0 | F20: =F11*Assumptions!$E$12 -> 0 | G20: =G11*Assumptions!$E$12 -> 0 | H20: =H11*Assumptions!$E$12 -> 0 | I20: =I11*Assumptions!$E$12 -> 0 | J20: =J11*Assumptions!$E$12 -> 0 | ... BJ20: =BJ11*Assumptions!$E$12 -> 5207984.6
A21: =Assumptions!A13 -> China → Gambia | B21: USD | C21: =C12*Assumptions!$E$13 -> 0 | D21: =D12*Assumptions!$E$13 -> 0 | E21: =E12*Assumptions!$E$13 -> 0 | F21: =F12*Assumptions!$E$13 -> 0 | G21: =G12*Assumptions!$E$13 -> 0 | H21: =H12*Assumptions!$E$13 -> 0 | I21: =I12*Assumptions!$E$13 -> 0 | J21: =J12*Assumptions!$E$13 -> 0 | ... BJ21: =BJ12*Assumptions!$E$13 -> 4680486.8
A22: =Assumptions!A14 -> USA → Gambia | B22: USD | C22: =C13*Assumptions!$E$14 -> 0 | D22: =D13*Assumptions!$E$14 -> 0 | E22: =E13*Assumptions!$E$14 -> 0 | F22: =F13*Assumptions!$E$14 -> 0 | G22: =G13*Assumptions!$E$14 -> 0 | H22: =H13*Assumptions!$E$14 -> 0 | I22: =I13*Assumptions!$E$14 -> 0 | J22: =J13*Assumptions!$E$14 -> 0 | ... BJ22: =BJ13*Assumptions!$E$14 -> 3345819
A23: =Assumptions!A15 -> Regional: Senegal (Dakar) | B23: USD | C23: =C14*Assumptions!$E$15 -> 0 | D23: =D14*Assumptions!$E$15 -> 0 | E23: =E14*Assumptions!$E$15 -> 0 | F23: =F14*Assumptions!$E$15 -> 0 | G23: =G14*Assumptions!$E$15 -> 0 | H23: =H14*Assumptions!$E$15 -> 0 | I23: =I14*Assumptions!$E$15 -> 0 | J23: =J14*Assumptions!$E$15 -> 0 | ... BJ23: =BJ14*Assumptions!$E$15 -> 2884846.5
A24: =Assumptions!A16 -> Regional: Guinea (Conakry) | B24: USD | C24: =C15*Assumptions!$E$16 -> 0 | D24: =D15*Assumptions!$E$16 -> 0 | E24: =E15*Assumptions!$E$16 -> 0 | F24: =F15*Assumptions!$E$16 -> 0 | G24: =G15*Assumptions!$E$16 -> 0 | H24: =H15*Assumptions!$E$16 -> 0 | I24: =I15*Assumptions!$E$16 -> 0 | J24: =J15*Assumptions!$E$16 -> 0 | ... BJ24: =BJ15*Assumptions!$E$16 -> 1372282.9
A25: =Assumptions!A17 -> Regional: Guinea-Bissau (Bissau) | B25: USD | C25: =C16*Assumptions!$E$17 -> 0 | D25: =D16*Assumptions!$E$17 -> 0 | E25: =E16*Assumptions!$E$17 -> 0 | F25: =F16*Assumptions!$E$17 -> 0 | G25: =G16*Assumptions!$E$17 -> 0 | H25: =H16*Assumptions!$E$17 -> 0 | I25: =I16*Assumptions!$E$17 -> 0 | J25: =J16*Assumptions!$E$17 -> 0 | ... BJ25: =BJ16*Assumptions!$E$17 -> 812813.73
A26: Total volume | B26: USD | C26: =SUM(C20:C25) -> 0 | D26: =SUM(D20:D25) -> 0 | E26: =SUM(E20:E25) -> 0 | F26: =SUM(F20:F25) -> 0 | G26: =SUM(G20:G25) -> 0 | H26: =SUM(H20:H25) -> 0 | I26: =SUM(I20:I25) -> 0 | J26: =SUM(J20:J25) -> 0 | ... BJ26: =SUM(BJ20:BJ25) -> 18304234
A27: of which Gambia-bound (UK+China+USA) | B27: USD | C27: =SUMPRODUCT(C20:C25,Assumptions!$I$12:$I$17) -> 0 | D27: =SUMPRODUCT(D20:D25,Assumptions!$I$12:$I$17) -> 0 | E27: =SUMPRODUCT(E20:E25,Assumptions!$I$12:$I$17) -> 0 | F27: =SUMPRODUCT(F20:F25,Assumptions!$I$12:$I$17) -> 0 | G27: =SUMPRODUCT(G20:G25,Assumptions!$I$12:$I$17) -> 0 | H27: =SUMPRODUCT(H20:H25,Assumptions!$I$12:$I$17) -> 0 | I27: =SUMPRODUCT(I20:I25,Assumptions!$I$12:$I$17) -> 0 | J27: =SUMPRODUCT(J20:J25,Assumptions!$I$12:$I$17) -> 0 | ... BJ27: =SUMPRODUCT(BJ20:BJ25,Assumptions!$I$12:$I$17) -> 13234290
A29: REVENUE (USD)
A30: Transfer fee revenue | B30: USD | C30: =SUMPRODUCT(C20:C25,Assumptions!$F$12:$F$17) -> 0 | D30: =SUMPRODUCT(D20:D25,Assumptions!$F$12:$F$17) -> 0 | E30: =SUMPRODUCT(E20:E25,Assumptions!$F$12:$F$17) -> 0 | F30: =SUMPRODUCT(F20:F25,Assumptions!$F$12:$F$17) -> 0 | G30: =SUMPRODUCT(G20:G25,Assumptions!$F$12:$F$17) -> 0 | H30: =SUMPRODUCT(H20:H25,Assumptions!$F$12:$F$17) -> 0 | I30: =SUMPRODUCT(I20:I25,Assumptions!$F$12:$F$17) -> 0 | J30: =SUMPRODUCT(J20:J25,Assumptions!$F$12:$F$17) -> 0 | ... BJ30: =SUMPRODUCT(BJ20:BJ25,Assumptions!$F$12:$F$17) -> 429866.88
A31: FX margin revenue | B31: USD | C31: =SUMPRODUCT(C20:C25,Assumptions!$G$12:$G$17) -> 0 | D31: =SUMPRODUCT(D20:D25,Assumptions!$G$12:$G$17) -> 0 | E31: =SUMPRODUCT(E20:E25,Assumptions!$G$12:$G$17) -> 0 | F31: =SUMPRODUCT(F20:F25,Assumptions!$G$12:$G$17) -> 0 | G31: =SUMPRODUCT(G20:G25,Assumptions!$G$12:$G$17) -> 0 | H31: =SUMPRODUCT(H20:H25,Assumptions!$G$12:$G$17) -> 0 | I31: =SUMPRODUCT(I20:I25,Assumptions!$G$12:$G$17) -> 0 | J31: =SUMPRODUCT(J20:J25,Assumptions!$G$12:$G$17) -> 0 | ... BJ31: =SUMPRODUCT(BJ20:BJ25,Assumptions!$G$12:$G$17) -> 270331.94
A32: Total revenue | B32: USD | C32: =C30+C31 -> 0 | D32: =D30+D31 -> 0 | E32: =E30+E31 -> 0 | F32: =F30+F31 -> 0 | G32: =G30+G31 -> 0 | H32: =H30+H31 -> 0 | I32: =I30+I31 -> 0 | J32: =J30+J31 -> 0 | ... BJ32: =BJ30+BJ31 -> 700198.81
A34: VARIABLE COSTS (USD)
A35: =Assumptions!A26 -> Payout partner / agent commission | B35: USD | C35: =C$26*Assumptions!$B$26 -> 0 | D35: =D$26*Assumptions!$B$26 -> 0 | E35: =E$26*Assumptions!$B$26 -> 0 | F35: =F$26*Assumptions!$B$26 -> 0 | G35: =G$26*Assumptions!$B$26 -> 0 | H35: =H$26*Assumptions!$B$26 -> 0 | I35: =I$26*Assumptions!$B$26 -> 0 | J35: =J$26*Assumptions!$B$26 -> 0 | ... BJ35: =BJ$26*Assumptions!$B$26 -> 128129.64
A36: =Assumptions!A27 -> Origin send-point / agent commission | B36: USD | C36: =C$26*Assumptions!$B$27 -> 0 | D36: =D$26*Assumptions!$B$27 -> 0 | E36: =E$26*Assumptions!$B$27 -> 0 | F36: =F$26*Assumptions!$B$27 -> 0 | G36: =G$26*Assumptions!$B$27 -> 0 | H36: =H$26*Assumptions!$B$27 -> 0 | I36: =I$26*Assumptions!$B$27 -> 0 | J36: =J$26*Assumptions!$B$27 -> 0 | ... BJ36: =BJ$26*Assumptions!$B$27 -> 45760.584
A37: =Assumptions!A28 -> Banking, settlement & FX execution | B37: USD | C37: =C$26*Assumptions!$B$28 -> 0 | D37: =D$26*Assumptions!$B$28 -> 0 | E37: =E$26*Assumptions!$B$28 -> 0 | F37: =F$26*Assumptions!$B$28 -> 0 | G37: =G$26*Assumptions!$B$28 -> 0 | H37: =H$26*Assumptions!$B$28 -> 0 | I37: =I$26*Assumptions!$B$28 -> 0 | J37: =J$26*Assumptions!$B$28 -> 0 | ... BJ37: =BJ$26*Assumptions!$B$28 -> 54912.701
A38: =Assumptions!A29 -> Fraud & loss provision | B38: USD | C38: =C$26*Assumptions!$B$29 -> 0 | D38: =D$26*Assumptions!$B$29 -> 0 | E38: =E$26*Assumptions!$B$29 -> 0 | F38: =F$26*Assumptions!$B$29 -> 0 | G38: =G$26*Assumptions!$B$29 -> 0 | H38: =H$26*Assumptions!$B$29 -> 0 | I38: =I$26*Assumptions!$B$29 -> 0 | J38: =J$26*Assumptions!$B$29 -> 0 | ... BJ38: =BJ$26*Assumptions!$B$29 -> 18304.234
A39: =Assumptions!A30 -> KYC, screening, SMS/WhatsApp | B39: USD | C39: =C$26*Assumptions!$B$30 -> 0 | D39: =D$26*Assumptions!$B$30 -> 0 | E39: =E$26*Assumptions!$B$30 -> 0 | F39: =F$26*Assumptions!$B$30 -> 0 | G39: =G$26*Assumptions!$B$30 -> 0 | H39: =H$26*Assumptions!$B$30 -> 0 | I39: =I$26*Assumptions!$B$30 -> 0 | J39: =J$26*Assumptions!$B$30 -> 0 | ... BJ39: =BJ$26*Assumptions!$B$30 -> 21965.08
A40: =Assumptions!A31 -> Cash logistics & cash-in-transit insurance | B40: USD | C40: =C$26*Assumptions!$B$31 -> 0 | D40: =D$26*Assumptions!$B$31 -> 0 | E40: =E$26*Assumptions!$B$31 -> 0 | F40: =F$26*Assumptions!$B$31 -> 0 | G40: =G$26*Assumptions!$B$31 -> 0 | H40: =H$26*Assumptions!$B$31 -> 0 | I40: =I$26*Assumptions!$B$31 -> 0 | J40: =J$26*Assumptions!$B$31 -> 0 | ... BJ40: =BJ$26*Assumptions!$B$31 -> 27456.35
A41: Total variable costs | B41: USD | C41: =SUM(C35:C40) -> 0 | D41: =SUM(D35:D40) -> 0 | E41: =SUM(E35:E40) -> 0 | F41: =SUM(F35:F40) -> 0 | G41: =SUM(G35:G40) -> 0 | H41: =SUM(H35:H40) -> 0 | I41: =SUM(I35:I40) -> 0 | J41: =SUM(J35:J40) -> 0 | ... BJ41: =SUM(BJ35:BJ40) -> 296528.58
A42: Contribution | B42: USD | C42: =C32-C41 -> 0 | D42: =D32-D41 -> 0 | E42: =E32-E41 -> 0 | F42: =F32-F41 -> 0 | G42: =G32-G41 -> 0 | H42: =H32-H41 -> 0 | I42: =I32-I41 -> 0 | J42: =J32-J41 -> 0 | ... BJ42: =BJ32-BJ41 -> 403670.23
A44: FIXED OPERATING COSTS (USD)
A45: Payroll | B45: USD | C45: =INDEX(Assumptions!$B$36:$F$36,C$5)/12*Assumptions!$E$3 -> 60458.333 | D45: =INDEX(Assumptions!$B$36:$F$36,D$5)/12*Assumptions!$E$3 -> 60458.333 | E45: =INDEX(Assumptions!$B$36:$F$36,E$5)/12*Assumptions!$E$3 -> 60458.333 | F45: =INDEX(Assumptions!$B$36:$F$36,F$5)/12*Assumptions!$E$3 -> 60458.333 | G45: =INDEX(Assumptions!$B$36:$F$36,G$5)/12*Assumptions!$E$3 -> 60458.333 | H45: =INDEX(Assumptions!$B$36:$F$36,H$5)/12*Assumptions!$E$3 -> 60458.333 | I45: =INDEX(Assumptions!$B$36:$F$36,I$5)/12*Assumptions!$E$3 -> 60458.333 | J45: =INDEX(Assumptions!$B$36:$F$36,J$5)/12*Assumptions!$E$3 -> 60458.333 | ... BJ45: =INDEX(Assumptions!$B$36:$F$36,BJ$5)/12*Assumptions!$E$3 -> 170166.67
A46: Premises & send points | B46: USD | C46: =INDEX(Assumptions!$B$37:$F$37,C$5)/12*Assumptions!$E$3 -> 5000 | D46: =INDEX(Assumptions!$B$37:$F$37,D$5)/12*Assumptions!$E$3 -> 5000 | E46: =INDEX(Assumptions!$B$37:$F$37,E$5)/12*Assumptions!$E$3 -> 5000 | F46: =INDEX(Assumptions!$B$37:$F$37,F$5)/12*Assumptions!$E$3 -> 5000 | G46: =INDEX(Assumptions!$B$37:$F$37,G$5)/12*Assumptions!$E$3 -> 5000 | H46: =INDEX(Assumptions!$B$37:$F$37,H$5)/12*Assumptions!$E$3 -> 5000 | I46: =INDEX(Assumptions!$B$37:$F$37,I$5)/12*Assumptions!$E$3 -> 5000 | J46: =INDEX(Assumptions!$B$37:$F$37,J$5)/12*Assumptions!$E$3 -> 5000 | ... BJ46: =INDEX(Assumptions!$B$37:$F$37,BJ$5)/12*Assumptions!$E$3 -> 33333.333
...

Sheet Annual
A1: Annual summary
A2: ="Scenario: "&Assumptions!C3 -> Scenario: Base
A3: Year index | C3: 1 | D3: 2 | E3: 3 | F3: 4 | G3: 5
A4: USD unless stated | B4: Unit | C4: Y1 | D4: Y2 | E4: Y3 | F4: Y4 | G4: Y5
A5: Transfers | B5: count | C5: =SUMIF(Monthly!$C$5:$BJ$5,C$3,Monthly!$C$17:$BJ$17) -> 5130.032 | D5: =SUMIF(Monthly!$C$5:$BJ$5,D$3,Monthly!$C$17:$BJ$17) -> 179228.9 | E5: =SUMIF(Monthly!$C$5:$BJ$5,E$3,Monthly!$C$17:$BJ$17) -> 528262.59 | F5: =SUMIF(Monthly!$C$5:$BJ$5,F$3,Monthly!$C$17:$BJ$17) -> 825180.51 | G5: =SUMIF(Monthly!$C$5:$BJ$5,G$3,Monthly!$C$17:$BJ$17) -> 943399.38
A6: Volume sent | B6: USD | C6: =SUMIF(Monthly!$C$5:$BJ$5,C$3,Monthly!$C$26:$BJ$26) -> 1179907.4 | D6: =SUMIF(Monthly!$C$5:$BJ$5,D$3,Monthly!$C$26:$BJ$26) -> 46431597 | E6: =SUMIF(Monthly!$C$5:$BJ$5,E$3,Monthly!$C$26:$BJ$26) -> 1.2069937e+08 | F6: =SUMIF(Monthly!$C$5:$BJ$5,F$3,Monthly!$C$26:$BJ$26) -> 1.6876115e+08 | G6: =SUMIF(Monthly!$C$5:$BJ$5,G$3,Monthly!$C$26:$BJ$26) -> 1.8753662e+08
A7: UK → Gambia | B7: USD | C7: =SUMIF(Monthly!$C$5:$BJ$5,C$3,Monthly!$C$20:$BJ$20) -> 1179907.4 | D7: =SUMIF(Monthly!$C$5:$BJ$5,D$3,Monthly!$C$20:$BJ$20) -> 27139792 | E7: =SUMIF(Monthly!$C$5:$BJ$5,E$3,Monthly!$C$20:$BJ$20) -> 45022614 | F7: =SUMIF(Monthly!$C$5:$BJ$5,F$3,Monthly!$C$20:$BJ$20) -> 51601337 | G7: =SUMIF(Monthly!$C$5:$BJ$5,G$3,Monthly!$C$20:$BJ$20) -> 54021513
A8: China → Gambia | B8: USD | C8: =SUMIF(Monthly!$C$5:$BJ$5,C$3,Monthly!$C$21:$BJ$21) -> 0 | D8: =SUMIF(Monthly!$C$5:$BJ$5,D$3,Monthly!$C$21:$BJ$21) -> 14765834 | E8: =SUMIF(Monthly!$C$5:$BJ$5,E$3,Monthly!$C$21:$BJ$21) -> 36992640 | F8: =SUMIF(Monthly!$C$5:$BJ$5,F$3,Monthly!$C$21:$BJ$21) -> 45295771 | G8: =SUMIF(Monthly!$C$5:$BJ$5,G$3,Monthly!$C$21:$BJ$21) -> 48350322
A9: USA → Gambia | B9: USD | C9: =SUMIF(Monthly!$C$5:$BJ$5,C$3,Monthly!$C$22:$BJ$22) -> 0 | D9: =SUMIF(Monthly!$C$5:$BJ$5,D$3,Monthly!$C$22:$BJ$22) -> 4525971.7 | E9: =SUMIF(Monthly!$C$5:$BJ$5,E$3,Monthly!$C$22:$BJ$22) -> 22929900 | F9: =SUMIF(Monthly!$C$5:$BJ$5,F$3,Monthly!$C$22:$BJ$22) -> 31286597 | G9: =SUMIF(Monthly!$C$5:$BJ$5,G$3,Monthly!$C$22:$BJ$22) -> 34360854
A10: Senegal | B10: USD | C10: =SUMIF(Monthly!$C$5:$BJ$5,C$3,Monthly!$C$23:$BJ$23) -> 0 | D10: =SUMIF(Monthly!$C$5:$BJ$5,D$3,Monthly!$C$23:$BJ$23) -> 0 | E10: =SUMIF(Monthly!$C$5:$BJ$5,E$3,Monthly!$C$23:$BJ$23) -> 12631291 | F10: =SUMIF(Monthly!$C$5:$BJ$5,F$3,Monthly!$C$23:$BJ$23) -> 24755812 | G10: =SUMIF(Monthly!$C$5:$BJ$5,G$3,Monthly!$C$23:$BJ$23) -> 29216173
A11: Guinea (Conakry) | B11: USD | C11: =SUMIF(Monthly!$C$5:$BJ$5,C$3,Monthly!$C$24:$BJ$24) -> 0 | D11: =SUMIF(Monthly!$C$5:$BJ$5,D$3,Monthly!$C$24:$BJ$24) -> 0 | E11: =SUMIF(Monthly!$C$5:$BJ$5,E$3,Monthly!$C$24:$BJ$24) -> 1961254.4 | F11: =SUMIF(Monthly!$C$5:$BJ$5,F$3,Monthly!$C$24:$BJ$24) -> 9936290 | G11: =SUMIF(Monthly!$C$5:$BJ$5,G$3,Monthly!$C$24:$BJ$24) -> 13557525
A12: Guinea-Bissau (Bissau) | B12: USD | C12: =SUMIF(Monthly!$C$5:$BJ$5,C$3,Monthly!$C$25:$BJ$25) -> 0 | D12: =SUMIF(Monthly!$C$5:$BJ$5,D$3,Monthly!$C$25:$BJ$25) -> 0 | E12: =SUMIF(Monthly!$C$5:$BJ$5,E$3,Monthly!$C$25:$BJ$25) -> 1161666.1 | F12: =SUMIF(Monthly!$C$5:$BJ$5,F$3,Monthly!$C$25:$BJ$25) -> 5885341 | G12: =SUMIF(Monthly!$C$5:$BJ$5,G$3,Monthly!$C$25:$BJ$25) -> 8030226.6
A13: check (should be 0) | C13: =SUM(C7:C12)-C6 -> 0 | D13: =SUM(D7:D12)-D6 -> 0 | E13: =SUM(E7:E12)-E6 -> 0 | F13: =SUM(F7:F12)-F6 -> 0 | G13: =SUM(G7:G12)-G6 -> 0
A14: Fee revenue | B14: USD | C14: =SUMIF(Monthly!$C$5:$BJ$5,C$3,Monthly!$C$30:$BJ$30) -> 29497.684 | D14: =SUMIF(Monthly!$C$5:$BJ$5,D$3,Monthly!$C$30:$BJ$30) -> 1092674.7 | E14: =SUMIF(Monthly!$C$5:$BJ$5,E$3,Monthly!$C$30:$BJ$30) -> 2811822.1 | F14: =SUMIF(Monthly!$C$5:$BJ$5,F$3,Monthly!$C$30:$BJ$30) -> 3954567.5 | G14: =SUMIF(Monthly!$C$5:$BJ$5,G$3,Monthly!$C$30:$BJ$30) -> 4402603.5
A15: FX margin revenue | B15: USD | C15: =SUMIF(Monthly!$C$5:$BJ$5,C$3,Monthly!$C$31:$BJ$31) -> 17698.611 | D15: =SUMIF(Monthly!$C$5:$BJ$5,D$3,Monthly!$C$31:$BJ$31) -> 696473.96 | E15: =SUMIF(Monthly!$C$5:$BJ$5,E$3,Monthly!$C$31:$BJ$31) -> 1778917.9 | F15: =SUMIF(Monthly!$C$5:$BJ$5,F$3,Monthly!$C$31:$BJ$31) -> 2489175.2 | G15: =SUMIF(Monthly!$C$5:$BJ$5,G$3,Monthly!$C$31:$BJ$31) -> 2769097.7
A16: Total revenue | B16: USD | C16: =SUMIF(Monthly!$C$5:$BJ$5,C$3,Monthly!$C$32:$BJ$32) -> 47196.295 | D16: =SUMIF(Monthly!$C$5:$BJ$5,D$3,Monthly!$C$32:$BJ$32) -> 1789148.6 | E16: =SUMIF(Monthly!$C$5:$BJ$5,E$3,Monthly!$C$32:$BJ$32) -> 4590740 | F16: =SUMIF(Monthly!$C$5:$BJ$5,F$3,Monthly!$C$32:$BJ$32) -> 6443742.7 | G16: =SUMIF(Monthly!$C$5:$BJ$5,G$3,Monthly!$C$32:$BJ$32) -> 7171701.2
A17: Take rate (revenue / volume) | C17: =IFERROR(C16/C6,0) -> 0.04 | D17: =IFERROR(D16/D6,0) -> 0.038532997 | E17: =IFERROR(E16/E6,0) -> 0.0380345 | F17: =IFERROR(F16/F6,0) -> 0.03818262 | G17: =IFERROR(G16/G6,0) -> 0.038241605
A18: Variable costs | B18: USD | C18: =SUMIF(Monthly!$C$5:$BJ$5,C$3,Monthly!$C$41:$BJ$41) -> 19114.499 | D18: =SUMIF(Monthly!$C$5:$BJ$5,D$3,Monthly!$C$41:$BJ$41) -> 752191.88 | E18: =SUMIF(Monthly!$C$5:$BJ$5,E$3,Monthly!$C$41:$BJ$41) -> 1955329.7 | F18: =SUMIF(Monthly!$C$5:$BJ$5,F$3,Monthly!$C$41:$BJ$41) -> 2733930.6 | G18: =SUMIF(Monthly!$C$5:$BJ$5,G$3,Monthly!$C$41:$BJ$41) -> 3038093.2
A19: Contribution | B19: USD | C19: =SUMIF(Monthly!$C$5:$BJ$5,C$3,Monthly!$C$42:$BJ$42) -> 28081.795 | D19: =SUMIF(Monthly!$C$5:$BJ$5,D$3,Monthly!$C$42:$BJ$42) -> 1036956.7 | E19: =SUMIF(Monthly!$C$5:$BJ$5,E$3,Monthly!$C$42:$BJ$42) -> 2635410.2 | F19: =SUMIF(Monthly!$C$5:$BJ$5,F$3,Monthly!$C$42:$BJ$42) -> 3709812.2 | G19: =SUMIF(Monthly!$C$5:$BJ$5,G$3,Monthly!$C$42:$BJ$42) -> 4133608
A20: Contribution margin (% of revenue) | C20: =IFERROR(C19/C16,0) -> 0.595 | D20: =IFERROR(D19/D16,0) -> 0.57958111 | E20: =IFERROR(E19/E16,0) -> 0.5740709 | F20: =IFERROR(F19/F16,0) -> 0.57572319 | G20: =IFERROR(G19/G16,0) -> 0.57637761
A21: Payroll | B21: USD | C21: =SUMIF(Monthly!$C$5:$BJ$5,C$3,Monthly!$C$45:$BJ$45) -> 725500 | D21: =SUMIF(Monthly!$C$5:$BJ$5,D$3,Monthly!$C$45:$BJ$45) -> 1108500 | E21: =SUMIF(Monthly!$C$5:$BJ$5,E$3,Monthly!$C$45:$BJ$45) -> 1557500 | F21: =SUMIF(Monthly!$C$5:$BJ$5,F$3,Monthly!$C$45:$BJ$45) -> 1892500 | G21: =SUMIF(Monthly!$C$5:$BJ$5,G$3,Monthly!$C$45:$BJ$45) -> 2042000
A22: Premises & send points | B22: USD | C22: =SUMIF(Monthly!$C$5:$BJ$5,C$3,Monthly!$C$46:$BJ$46) -> 60000 | D22: =SUMIF(Monthly!$C$5:$BJ$5,D$3,Monthly!$C$46:$BJ$46) -> 200000 | E22: =SUMIF(Monthly!$C$5:$BJ$5,E$3,Monthly!$C$46:$BJ$46) -> 300000 | F22: =SUMIF(Monthly!$C$5:$BJ$5,F$3,Monthly!$C$46:$BJ$46) -> 360000 | G22: =SUMIF(Monthly!$C$5:$BJ$5,G$3,Monthly!$C$46:$BJ$46) -> 400000
A23: Licensing, legal & compliance | B23: USD | C23: =SUMIF(Monthly!$C$5:$BJ$5,C$3,Monthly!$C$47:$BJ$47) -> 280000 | D23: =SUMIF(Monthly!$C$5:$BJ$5,D$3,Monthly!$C$47:$BJ$47) -> 360000 | E23: =SUMIF(Monthly!$C$5:$BJ$5,E$3,Monthly!$C$47:$BJ$47) -> 360000 | F23: =SUMIF(Monthly!$C$5:$BJ$5,F$3,Monthly!$C$47:$BJ$47) -> 380000 | G23: =SUMIF(Monthly!$C$5:$BJ$5,G$3,Monthly!$C$47:$BJ$47) -> 400000
A24: Technology & vendors | B24: USD | C24: =SUMIF(Monthly!$C$5:$BJ$5,C$3,Monthly!$C$48:$BJ$48) -> 140000 | D24: =SUMIF(Monthly!$C$5:$BJ$5,D$3,Monthly!$C$48:$BJ$48) -> 220000 | E24: =SUMIF(Monthly!$C$5:$BJ$5,E$3,Monthly!$C$48:$BJ$48) -> 300000 | F24: =SUMIF(Monthly!$C$5:$BJ$5,F$3,Monthly!$C$48:$BJ$48) -> 380000 | G24: =SUMIF(Monthly!$C$5:$BJ$5,G$3,Monthly!$C$48:$BJ$48) -> 420000
A25: Marketing & community | B25: USD | C25: =SUMIF(Monthly!$C$5:$BJ$5,C$3,Monthly!$C$49:$BJ$49) -> 50000 | D25: =SUMIF(Monthly!$C$5:$BJ$5,D$3,Monthly!$C$49:$BJ$49) -> 220000 | E25: =SUMIF(Monthly!$C$5:$BJ$5,E$3,Monthly!$C$49:$BJ$49) -> 320000 | F25: =SUMIF(Monthly!$C$5:$BJ$5,F$3,Monthly!$C$49:$BJ$49) -> 340000 | G25: =SUMIF(Monthly!$C$5:$BJ$5,G$3,Monthly!$C$49:$BJ$49) -> 360000
A26: G&A | B26: USD | C26: =SUMIF(Monthly!$C$5:$BJ$5,C$3,Monthly!$C$50:$BJ$50) -> 80000 | D26: =SUMIF(Monthly!$C$5:$BJ$5,D$3,Monthly!$C$50:$BJ$50) -> 150000 | E26: =SUMIF(Monthly!$C$5:$BJ$5,E$3,Monthly!$C$50:$BJ$50) -> 200000 | F26: =SUMIF(Monthly!$C$5:$BJ$5,F$3,Monthly!$C$50:$BJ$50) -> 240000 | G26: =SUMIF(Monthly!$C$5:$BJ$5,G$3,Monthly!$C$50:$BJ$50) -> 260000
A27: Total fixed costs | B27: USD | C27: =SUMIF(Monthly!$C$5:$BJ$5,C$3,Monthly!$C$51:$BJ$51) -> 1335500 | D27: =SUMIF(Monthly!$C$5:$BJ$5,D$3,Monthly!$C$51:$BJ$51) -> 2258500 | E27: =SUMIF(Monthly!$C$5:$BJ$5,E$3,Monthly!$C$51:$BJ$51) -> 3037500 | F27: =SUMIF(Monthly!$C$5:$BJ$5,F$3,Monthly!$C$51:$BJ$51) -> 3592500 | G27: =SUMIF(Monthly!$C$5:$BJ$5,G$3,Monthly!$C$51:$BJ$51) -> 3882000
A28: EBITDA margin (% of revenue) | C28: =IF(C16<250000,"n/m",C29/C16) -> n/m | D28: =IF(D16<250000,"n/m",D29/D16) -> -0.68275114 | E28: =IF(E16<250000,"n/m",E29/E16) -> -0.087587135 | F28: =IF(F16<250000,"n/m",F29/F16) -> 0.018205593 | G28: =IF(G16<250000,"n/m",G29/G16) -> 0.035083447
A29: EBITDA | B29: USD | C29: =SUMIF(Monthly!$C$5:$BJ$5,C$3,Monthly!$C$53:$BJ$53) -> -1307418.2 | D29: =SUMIF(Monthly!$C$5:$BJ$5,D$3,Monthly!$C$53:$BJ$53) -> -1221543.3 | E29: =SUMIF(Monthly!$C$5:$BJ$5,E$3,Monthly!$C$53:$BJ$53) -> -402089.76 | F29: =SUMIF(Monthly!$C$5:$BJ$5,F$3,Monthly!$C$53:$BJ$53) -> 117312.16 | G29: =SUMIF(Monthly!$C$5:$BJ$5,G$3,Monthly!$C$53:$BJ$53) -> 251608
A31: Capital expenditure | B31: USD | C31: =SUMIF(Monthly!$C$5:$BJ$5,C$3,Monthly!$C$56:$BJ$56) -> 200000 | D31: =SUMIF(Monthly!$C$5:$BJ$5,D$3,Monthly!$C$56:$BJ$56) -> 250000 | E31: =SUMIF(Monthly!$C$5:$BJ$5,E$3,Monthly!$C$56:$BJ$56) -> 300000 | F31: =SUMIF(Monthly!$C$5:$BJ$5,F$3,Monthly!$C$56:$BJ$56) -> 300000 | G31: =SUMIF(Monthly!$C$5:$BJ$5,G$3,Monthly!$C$56:$BJ$56) -> 300000
A32: Equity raised | B32: USD | C32: =SUMIF(Monthly!$C$5:$BJ$5,C$3,Monthly!$C$60:$BJ$60) -> 4000000 | D32: =SUMIF(Monthly!$C$5:$BJ$5,D$3,Monthly!$C$60:$BJ$60) -> 5000000 | E32: =SUMIF(Monthly!$C$5:$BJ$5,E$3,Monthly!$C$60:$BJ$60) -> 0 | F32: =SUMIF(Monthly!$C$5:$BJ$5,F$3,Monthly!$C$60:$BJ$60) -> 0 | G32: =SUMIF(Monthly!$C$5:$BJ$5,G$3,Monthly!$C$60:$BJ$60) -> 0
A34: Balance & market indicators | B34: Unit | C34: Y1 | D34: Y2 | E34: Y3 | F34: Y4 | G34: Y5
A35: Year-end prefunded float required | B35: USD | C35: =INDEX(Monthly!$C$57:$BJ$57,12) -> 67675.973 | D35: =INDEX(Monthly!$C$57:$BJ$57,24) -> 642085.69 | E35: =INDEX(Monthly!$C$57:$BJ$57,36) -> 1186591 | F35: =INDEX(Monthly!$C$57:$BJ$57,48) -> 1434245.7 | G35: =INDEX(Monthly!$C$57:$BJ$57,60) -> 1525352.8
A36: Year-end closing cash | B36: USD | C36: =INDEX(Monthly!$C$61:$BJ$61,12) -> 2424905.8 | D36: =INDEX(Monthly!$C$61:$BJ$61,24) -> 5378952.8 | E36: =INDEX(Monthly!$C$61:$BJ$61,36) -> 4132357.8 | F36: =INDEX(Monthly!$C$61:$BJ$61,48) -> 3702015.2 | G36: =INDEX(Monthly!$C$61:$BJ$61,60) -> 3562516.1
A37: Lowest month-end cash in year | B37: USD | C37: =_xlfn.MINIFS(Monthly!$C$61:$BJ$61,Monthly!$C$5:$BJ$5,C$3) -> 2424905.8 | D37: =_xlfn.MINIFS(Monthly!$C$61:$BJ$61,Monthly!$C$5:$BJ$5,D$3) -> 795682.16 | E37: =_xlfn.MINIFS(Monthly!$C$61:$BJ$61,Monthly!$C$5:$BJ$5,E$3) -> 4132357.8 | F37: =_xlfn.MINIFS(Monthly!$C$61:$BJ$61,Monthly!$C$5:$BJ$5,F$3) -> 3702015.2 | G37: =_xlfn.MINIFS(Monthly!$C$61:$BJ$61,Monthly!$C$5:$BJ$5,G$3) -> 3562516.1
A38: Year-end active senders (est.) | B38: count | C38: =INDEX(Monthly!$C$65:$BJ$65,12) -> 4707.8938 | D38: =INDEX(Monthly!$C$65:$BJ$65,24) -> 38420.507 | E38: =INDEX(Monthly!$C$65:$BJ$65,36) -> 89330.401 | F38: =INDEX(Monthly!$C$65:$BJ$65,48) -> 114279.95 | G38: =INDEX(Monthly!$C$65:$BJ$65,60) -> 123458.37
A39: Year-end headcount | B39: count | C39: =Headcount!D16 -> 18 | D39: =Headcount!E16 -> 32 | E39: =Headcount!F16 -> 45 | F39: =Headcount!G16 -> 53 | G39: =Headcount!H16 -> 56
A40: Gambia-bound volume (UK+China+USA) | B40: USD | C40: =SUMIF(Monthly!$C$5:$BJ$5,C$3,Monthly!$C$27:$BJ$27) -> 1179907.4 | D40: =SUMIF(Monthly!$C$5:$BJ$5,D$3,Monthly!$C$27:$BJ$27) -> 46431597 | E40: =SUMIF(Monthly!$C$5:$BJ$5,E$3,Monthly!$C$27:$BJ$27) -> 1.0494515e+08 | F40: =SUMIF(Monthly!$C$5:$BJ$5,F$3,Monthly!$C$27:$BJ$27) -> 1.281837e+08 | G40: =SUMIF(Monthly!$C$5:$BJ$5,G$3,Monthly!$C$27:$BJ$27) -> 1.3673269e+08
A41: Gambia formal inflows (assumed) | B41: USD | C41: =Assumptions!$B$53*(1+Assumptions!$B$54)^(C$3+Assumptions!$B$55-2025) -> 1038565952 | D41: =Assumptions!$B$53*(1+Assumptions!$B$54)^(D$3+Assumptions!$B$55-2025) -> 1.1008799e+09 | E41: =Assumptions!$B$53*(1+Assumptions!$B$54)^(E$3+Assumptions!$B$55-2025) -> 1.1669327e+09 | F41: =Assumptions!$B$53*(1+Assumptions!$B$54)^(F$3+Assumptions!$B$55-2025) -> 1.2369487e+09 | G41: =Assumptions!$B$53*(1+Assumptions!$B$54)^(G$3+Assumptions!$B$55-2025) -> 1.3111656e+09
A42: Implied share of Gambia formal inflows | B42: % | C42: =IFERROR(C40/C41,0) -> 0.0011360929 | D42: =IFERROR(D40/D41,0) -> 0.042176805 | E42: =IFERROR(E40/E41,0) -> 0.089932482 | F42: =IFERROR(F40/F41,0) -> 0.10362896 | G42: =IFERROR(G40/G41,0) -> 0.10428331
...

Sheet Unit_Economics
A1: Unit economics per transfer
A3: Per average transfer (USD) | B3: UK→GM | C3: China→GM | D3: USA→GM | E3: Senegal | F3: Guinea | G3: Guinea-Bissau
A4: Average ticket | B4: =Assumptions!E12 -> 230 | C4: =Assumptions!E13 -> 320 | D4: =Assumptions!E14 -> 300 | E4: =Assumptions!E15 -> 110 | F4: =Assumptions!E16 -> 130 | G4: =Assumptions!E17 -> 110
A5: Fee revenue | B5: =B4*Assumptions!F12 -> 5.75 | C5: =C4*Assumptions!F13 -> 6.72 | D5: =D4*Assumptions!F14 -> 6.9 | E5: =E4*Assumptions!F15 -> 2.64 | F5: =F4*Assumptions!F16 -> 3.38 | G5: =G4*Assumptions!F17 -> 2.64
A6: FX margin revenue | B6: =B4*Assumptions!G12 -> 3.45 | C6: =C4*Assumptions!G13 -> 4.8 | D6: =D4*Assumptions!G14 -> 4.5 | E6: =E4*Assumptions!G15 -> 1.32 | F6: =F4*Assumptions!G16 -> 2.6 | G6: =G4*Assumptions!G17 -> 1.32
A7: Total revenue | B7: =B5+B6 -> 9.2 | C7: =C5+C6 -> 11.52 | D7: =D5+D6 -> 11.4 | E7: =E5+E6 -> 3.96 | F7: =F5+F6 -> 5.98 | G7: =G5+G6 -> 3.96
A8: Payout commission | B8: =B$4*Assumptions!$B$26 -> 1.61 | C8: =C$4*Assumptions!$B$26 -> 2.24 | D8: =D$4*Assumptions!$B$26 -> 2.1 | E8: =E$4*Assumptions!$B$26 -> 0.77 | F8: =F$4*Assumptions!$B$26 -> 0.91 | G8: =G$4*Assumptions!$B$26 -> 0.77
A9: Origin commission | B9: =B$4*Assumptions!$B$27 -> 0.575 | C9: =C$4*Assumptions!$B$27 -> 0.8 | D9: =D$4*Assumptions!$B$27 -> 0.75 | E9: =E$4*Assumptions!$B$27 -> 0.275 | F9: =F$4*Assumptions!$B$27 -> 0.325 | G9: =G$4*Assumptions!$B$27 -> 0.275
A10: Banking, settlement & FX | B10: =B$4*Assumptions!$B$28 -> 0.69 | C10: =C$4*Assumptions!$B$28 -> 0.96 | D10: =D$4*Assumptions!$B$28 -> 0.9 | E10: =E$4*Assumptions!$B$28 -> 0.33 | F10: =F$4*Assumptions!$B$28 -> 0.39 | G10: =G$4*Assumptions!$B$28 -> 0.33
A11: Fraud & loss | B11: =B$4*Assumptions!$B$29 -> 0.23 | C11: =C$4*Assumptions!$B$29 -> 0.32 | D11: =D$4*Assumptions!$B$29 -> 0.3 | E11: =E$4*Assumptions!$B$29 -> 0.11 | F11: =F$4*Assumptions!$B$29 -> 0.13 | G11: =G$4*Assumptions!$B$29 -> 0.11
A12: KYC / screening / SMS | B12: =B$4*Assumptions!$B$30 -> 0.276 | C12: =C$4*Assumptions!$B$30 -> 0.384 | D12: =D$4*Assumptions!$B$30 -> 0.36 | E12: =E$4*Assumptions!$B$30 -> 0.132 | F12: =F$4*Assumptions!$B$30 -> 0.156 | G12: =G$4*Assumptions!$B$30 -> 0.132
A13: Cash logistics & insurance | B13: =B$4*Assumptions!$B$31 -> 0.345 | C13: =C$4*Assumptions!$B$31 -> 0.48 | D13: =D$4*Assumptions!$B$31 -> 0.45 | E13: =E$4*Assumptions!$B$31 -> 0.165 | F13: =F$4*Assumptions!$B$31 -> 0.195 | G13: =G$4*Assumptions!$B$31 -> 0.165
A14: Total variable cost | B14: =SUM(B8:B13) -> 3.726 | C14: =SUM(C8:C13) -> 5.184 | D14: =SUM(D8:D13) -> 4.86 | E14: =SUM(E8:E13) -> 1.782 | F14: =SUM(F8:F13) -> 2.106 | G14: =SUM(G8:G13) -> 1.782
A15: Contribution per transfer | B15: =B7-B14 -> 5.474 | C15: =C7-C14 -> 6.336 | D15: =D7-D14 -> 6.54 | E15: =E7-E14 -> 2.178 | F15: =F7-F14 -> 3.874 | G15: =G7-G14 -> 2.178
A16: Contribution % of ticket | B16: =B15/B4 -> 0.0238 | C16: =C15/C4 -> 0.0198 | D16: =D15/D4 -> 0.0218 | E16: =E15/E4 -> 0.0198 | F16: =F15/F4 -> 0.0298 | G16: =G15/G4 -> 0.0198
A19: Customer lifetime value (UK→GM sender) | B19: Value
A20: Contribution per transfer (UK→GM) | B20: =B15 -> 5.474
A21: Transfers per year | B21: =Assumptions!B60 -> 9
A22: Contribution per active year | B22: =B20*B21 -> 49.266
A23: Expected active years over 3 years (retention curve) | B23: =Assumptions!B61+Assumptions!B62+Assumptions!B63 -> 2.17
A24: 3-year LTV (contribution) | B24: =B22*B23 -> 106.90722
A25: Blended CAC | B25: =Assumptions!B59 -> 22
A26: LTV : CAC | B26: =B24/B25 -> 4.8594191
A27: CAC payback (transfers) | B27: =B25/B20 -> 4.0189989
A30: Worked example: £200 cash sent London → Banjul (illustrative rates) | B30: Value
A31: Send amount (GBP) | B31: 200
A32: Transfer fee, tier £50.01–£200 (GBP) | B32: 4.99
A33: Total cash paid at counter (GBP) | B33: =B31+B32 -> 204.99
A34: Mid-market GBP/GMD (illustrative) | B34: 93.4
A35: FX margin | B35: 0.015
A36: Customer rate GBP/GMD | B36: =B34*(1-B35) -> 91.999
A37: Recipient receives (GMD) | B37: =B31*B36 -> 18399.8
A38: All-in cost to sender (fee + FX margin) as % of amount | B38: =(B32+B31*B35)/B31 -> 0.03995
A40: Market comparison: global average cost of sending ~US$200 is roughly 6–7% and Sub-Saharan Africa ~8% (World Bank Remittance Prices Worldwide — verify latest quarter). Bantaba target all-in: 3–4.5%.

Sheet Float_Treasury
A1: Prefunded payout float & treasury sizing
A3: USD | B3: End Y1 (M12) | C3: End Y2 (M24) | D3: End Y3 (M36) | E3: End Y4 (M48) | F3: End Y5 (M60)
A4: Monthly volume at year-end | B4: =INDEX(Monthly!$C$26:$BJ$26,12) -> 812111.68 | C4: =INDEX(Monthly!$C$26:$BJ$26,24) -> 7705028.3 | D4: =INDEX(Monthly!$C$26:$BJ$26,36) -> 14239092 | E4: =INDEX(Monthly!$C$26:$BJ$26,48) -> 17210949 | F4: =INDEX(Monthly!$C$26:$BJ$26,60) -> 18304234
A5: Average daily payout volume | B5: =B4/30 -> 27070.389 | C5: =C4/30 -> 256834.28 | D5: =D4/30 -> 474636.39 | E5: =E4/30 -> 573698.29 | F5: =F4/30 -> 610141.12
A6: Float cover (days) — Assumptions | B6: =Assumptions!$B$51 -> 2.5 | C6: =Assumptions!$B$51 -> 2.5 | D6: =Assumptions!$B$51 -> 2.5 | E6: =Assumptions!$B$51 -> 2.5 | F6: =Assumptions!$B$51 -> 2.5
A7: Prefunded float & settlement required | B7: =B5*B6 -> 67675.973 | C7: =C5*C6 -> 642085.69 | D7: =D5*D6 -> 1186591 | E7: =E5*E6 -> 1434245.7 | F7: =F5*F6 -> 1525352.8
A8: Peak-day buffer (Eid/Tobaski/December ×1.6) | B8: =B7*0.6 -> 40605.584 | C8: =C7*0.6 -> 385251.42 | D8: =D7*0.6 -> 711954.59 | E8: =E7*0.6 -> 860547.43 | F8: =F7*0.6 -> 915211.68
A9: Total treasury requirement incl. buffer | B9: =B7+B8 -> 108281.56 | C9: =C7+C8 -> 1027337.1 | D9: =D7+D8 -> 1898545.6 | E9: =E7+E8 -> 2294793.1 | F9: =F7+F8 -> 2440564.5
A10: Exposure cap: net open foreign-currency position ≤ 1.5 days of forecast payouts
A11: Maximum open FX position (USD) | B11: =B5*1.5 -> 40605.584 | C11: =C5*1.5 -> 385251.42 | D11: =D5*1.5 -> 711954.59 | E11: =E5*1.5 -> 860547.43 | F11: =F5*1.5 -> 915211.68
A13: Float is Bantaba's own money advanced to payout points (company-funded float) plus balances at payout partners. Agents also post a refundable security deposit (see Agent Network Playbook).

Sheet Scenarios
A1: Scenario snapshot (static values — switch Assumptions!B3 for live view)
A3: Metric | B3: Base (1.0× volume) | C3: Conservative (0.6× volume) | D3: Upside (1.3× volume)
A4: Volume sent Y3 (USD) | B4: 1.2069937e+08 | C4: 72419619 | D4: 1.5690918e+08
A5: Volume sent Y5 (USD) | B5: 1.8753662e+08 | C5: 1.1252197e+08 | D5: 2.437976e+08
A6: Revenue Y3 (USD) | B6: 4590740 | C6: 2754444 | D6: 5967962
A7: Revenue Y5 (USD) | B7: 7171701.2 | C7: 4303020.7 | D7: 9323211.5
A8: EBITDA Y3 (USD) | B8: -402089.76 | C8: -1456253.9 | D8: 388533.31
A9: EBITDA Y4 (USD) | B9: 117312.16 | C9: -1366612.7 | D9: 1230255.8
A10: EBITDA Y5 (USD) | B10: 251608 | C10: -1401835.2 | D10: 1491690.4
A11: Cumulative EBITDA trough (USD) | B11: -3001734.8 | C11: -7179678.6 | D11: -2318831.1
A12: Lowest month-end cash, 60 months (USD) | B12: 795682.16 | C12: -444890.32 | D12: 859449.3
A13: First EBITDA-positive month | B13: 34 | C13: not reached | D13: 24
A14: Share of Gambia inflows Y4 | B14: 0.10362896 | C14: 0.062177376 | D14: 0.13471765
A15: Year-end Y3 active senders (est.) | B15: 89330.401 | C15: 53598.24 | D15: 116129.52
A18: Reading: in the Conservative case the business does not reach EBITDA breakeven within five years on this cost base, and lowest cash falls below zero without bridge funding or a leaner cost plan (slower hiring, agent-led send points). The Series A trigger therefore includes a volume gate.
